~/.../assignments/05_gc$ make test
pytest -xv test.py cgc.py
========================================================== test session starts ==========================================================
platform linux -- Python 3.12.7, pytest-8.3.4, pluggy-1.5.0 -- /nix/store/nqlc7ymyglrsfx1hlssssq6zzy0hmk2c-python-wrapped-0.1.0/bin/python3
cachedir: .pytest_cache
rootdir: /home/runner/workspace/assignments/05_gc
plugins: pylint-0.21.0, mypy-0.10.3, flake8-1.3.0
collected 6 items / 1 error                                                                                                             

================================================================ ERRORS =================================================================
________________________________________________________ ERROR collecting cgc.py ________________________________________________________
../../.pythonlibs/lib/python3.12/site-packages/_pytest/python.py:493: in importtestmodule
    mod = import_path(
../../.pythonlibs/lib/python3.12/site-packages/_pytest/pathlib.py:587: in import_path
    importlib.import_module(module_name)
/nix/store/nb21sc3npfc8gvazwnrjxpvb5d48jysx-python3-3.12.7/lib/python3.12/importlib/__init__.py:90: in import_module
    return _bootstrap._gcd_import(name[level:], package, level)
<frozen importlib._bootstrap>:1387: in _gcd_import
    ???
<frozen importlib._bootstrap>:1360: in _find_and_load
    ???
<frozen importlib._bootstrap>:1331: in _find_and_load_unlocked
    ???
<frozen importlib._bootstrap>:935: in _load_unlocked
    ???
../../.pythonlibs/lib/python3.12/site-packages/_pytest/assertion/rewrite.py:175: in exec_module
    source_stat, co = _rewrite_test(fn, self.config)
../../.pythonlibs/lib/python3.12/site-packages/_pytest/assertion/rewrite.py:355: in _rewrite_test
    tree = ast.parse(source, filename=strfn)
/nix/store/nb21sc3npfc8gvazwnrjxpvb5d48jysx-python3-3.12.7/lib/python3.12/ast.py:52: in parse
    return compile(source, filename, mode, flags,
E     File "/home/runner/workspace/assignments/05_gc/cgc.py", line 63
E       ''' for line in file:
E   IndentationError: unexpected indent
======================================================== short test summary info ========================================================
ERROR cgc.py
!!!!!!!!!!!!!!!!!!!!!!!!!!!!!!!!!!!!!!!!!!!!!!!!!!!!!!! stopping after 1 failures !!!!!!!!!!!!!!!!!!!!!!!!!!!!!!!!!!!!!!!!!!!!!!!!!!!!!!!
!!!!!!!!!!!!!!!!!!!!!!!!!!!!!!!!!!!!!!!!!!!!!!!! Interrupted: 1 error during collection !!!!!!!!!!!!!!!!!!!!!!!!!!!!!!!!!!!!!!!!!!!!!!!!!
=========================================================== 1 error in 0.22s ============================================================
make: *** [Makefile:4: test] Error 2
~/.../assignments/05_gc$ 